Workbook

Sheet Notes & Sources
A1: Costco Wholesale Corporation (NASDAQ: COST) — Financial Model
A2: Equity Research Initiation Coverage — Task 2: Financial Modeling | Prepared September 20, 2026
A4: IMPORTANT — TIMING NOTE
A5: • Costco reports fiscal Q4/full-year 2026 GAAP results (net income, EPS, complete balance sheet) on September 24, 2026 — AFTER this model was built.
A6: • FY2026 net sales ($297,300mm) were already disclosed via Costco's August 2026 Sales Results press release (Sept 2, 2026) and are used as a hard input where noted.
A7: • Everything below the net-sales line for FY2026 (membership fees, costs, net income, EPS) is a PROJECTION pending the Sept 24 earnings release. Re-run this model against actual FY2026 results once reported.
A9: DATA QUALITY LEGEND
A10: • EXACT: Figure taken directly from a Costco SEC filing (10-K) or official earnings press release, cross-checked against at least one independent source.
A11: • ESTIMATED: Figure not independently located in the sources reviewed for this build; derived using a disclosed methodology (noted in the relevant cell comment). Flagged in blue with an explanatory comment throughout the model.
A12: • PROJECTED: Forward-looking analyst assumption for FY2026E-FY2030E, shown in bold blue and fully editable — the model recalculates automatically when these are changed.
A14: PRIMARY SOURCES USED
A15: • Costco Wholesale Corporation, Form 10-K, FY2025 (year ended Aug 31, 2025), filed Oct 2025. SEC EDGAR: sec.gov/Archives/edgar/data/909832/000090983225000101/cost-20250831.htm
... A35: • This model should be treated as a rigorous first draft for Task 3 (Valuation) and Task 5 (Report Assembly) — not as a substitute for Costco's own audited financial statements.

Sheet Executive Summary
B1: Costco Wholesale Corporation (NASDAQ: COST) — Equity Research
B2: Executive Summary | Prepared September 20, 2026 | Pre-Q4 FY2026 earnings (due Sept 24, 2026)
B4: Rating | C4: HOLD
B5: 12-Month Price Target | C5: $630
B6: Current Price (Sept 18-19, 2026) | C6: $895.00
B7: Implied Upside / (Downside) | C7: -29.6%
B8: Suggested Entry Zone (new capital) | C8: $600 - $700
B9: Wall Street Consensus (reference only) | C9: Buy / Moderate Buy, avg. target ~$1,072-1,089 (35 analysts)
B11: THE BOTTOM LINE
B12: This is not a 'the business is broken' call. Task 1's research confirms Costco remains one of the highest-quality franchises in retail: unmatched membership renewal rates (89.8% worldwide), a fee-funded margin structure competitors cannot easily replicate, and a management culture that has resisted trading member trust for near-term margin across four decades and three CEO transitions. The problem is the PRICE. Four independent valuation methods -- DCF, trading comps, historical own-multiple, and probability-weighted scenarios -- span $281 to $1,026 per share, but even the most generous methods here land below the $895 the stock trades at today, and well below the Street's own $1,072 average target. If you already own COST for the moat and the quality, a HOLD is defensible. If you're considering new money at $895, the math argues you're paying for growth that isn't guaranteed, with very little margin of safety if any single assumption -- comp-sales deceleration, Sam's Club fee-parity competition, a garden-variety multiple correction -- goes against you.
B14: VALUATION METHOD SUMMARY (see 'Valuation Summary' tab for full detail)
B15: Method | C15: Base Case Value | Weight
B16: DCF (5-yr explicit + Gordon Growth terminal value) | C16: $281 | weight 20%
B17: Trading Comps (peer EV/EBITDA + Fwd P/E, 5-peer set) | C17: $419 | weight 25%
B18: Historical Own-Multiple Reversion (3/5/10-yr avg P/E) | C18: $926 | weight 30%
B19: Scenario-Based (prob-weighted Bull/Base/Bear) | C19: $770 | weight 25%
B20: WEIGHTED AVERAGE TARGET | C20: $630 (rounded)
B22: WHY HOLD, NOT SELL
B23: A -30% implied gap vs. current price would, under strict quantitative banding (>15% upside=Buy, +/-15%=Hold, <-15%=Sell), argue for Sell/Underweight. Three things pull this back to HOLD: (1) Business quality is not in question -- the moat documented in Task 1 is real. (2) Valuation-method dispersion is unusually wide here ($281 to $1,026, a 3.6x spread), signaling genuine uncertainty about fair value rather than high-confidence overvaluation. (3) The stock has already pulled back ~18% from its 52-week high ($1,096.50) and trades below its own 3-year average multiple (51.75x trailing vs. current ~45-48x) -- some of the excess has already been worked off.
B25: WHY NOT BUY
B26: Every method used here that isn't anchored to Costco's own recent trading history -- DCF, peer comps -- lands 40-70% below the current price. The bull case for owning COST at $895 requires a specific bet: that the market's own extrapolation of Costco's historical premium is the right anchor, and that DCF/peer-comps are simply the wrong tools for this business. That may be correct -- it has been correct for a decade -- but it is a bet on continuity of an already-rich valuation, not a bet with a margin of safety.

Sheet Revenue Model
A1: Costco Wholesale Corporation — Revenue Model
A2: Task 2: Financial Modeling | Source: Costco Form 10-K filings, FY2021-FY2025 (SEC EDGAR); FY2026E anchored to actual disclosed net sales
A3: All figures in US$ millions except per-share and ratio data, unless noted. Fiscal year ends ~Aug 31 (52/53-week fiscal year).
A5: A. REVENUE BY MERCHANDISE CATEGORY
A6: ($ in millions) | B6: 2021A | C6: 2022A | D6: 2023A | E6: 2024A | F6: 2025A | G6: 2026E | H6: 2027E | I6: 2028E | J6: 2029E | K6: 2030E
A7: Foods and Sundries | B7: 77277 | C7: 85629 | D7: 96175 | E7: 101463 | F7: 109564 | G7: =F7*(1+G8) -> 120682.55 | H7: =G7*(1+H8) -> 129130.33 | I7: =H7*(1+I8) -> 137523.81 | J7: =I7*(1+J8) -> 146462.85 | K7: =J7*(1+K8) -> 155250.62
A8: YoY growth % | C8: =C7/B7-1 -> 0.10807873 | D8: =D7/C7-1 -> 0.12315921 | E8: =E7/D7-1 -> 0.054983104 | F8: =F7/E7-1 -> 0.079841913 | G8: 0.10148 | H8: 0.07 | I8: 0.065 | J8: 0.065 | K8: 0.06
A10: Non-Foods | B10: 55966 | C10: 61100 | D10: 60865 | E10: 63973 | F10: 71190 | G10: =F10*(1+G11) -> 78414.361 | H10: =G10*(1+H11) -> 83119.223 | I10: =H10*(1+I11) -> 87690.78 | J10: =I10*(1+J11) -> 92513.773 | K10: =J10*(1+K11) -> 97139.462
A11: YoY growth % | C11: =C10/B10-1 -> 0.091734267 | D11: =D10/C10-1 -> -0.0038461538 | E11: =E10/D10-1 -> 0.05106383 | F11: =F10/E10-1 -> 0.11281322 | G11: 0.10148 | H11: 0.06 | I11: 0.055 | J11: 0.055 | K11: 0.05
A13: Fresh Foods | B13: 27183 | C13: 29527 | D13: 31977 | E13: 34220 | F13: 37988 | G13: =F13*(1+G14) -> 41843.022 | H13: =G13*(1+H14) -> 44981.249 | I13: =H13*(1+I14) -> 48129.936 | J13: =I13*(1+J14) -> 51499.032 | K13: =J13*(1+K14) -> 54846.469
A14: YoY growth % | C14: =C13/B13-1 -> 0.086230365 | D14: =D13/C13-1 -> 0.082974904 | E14: =E13/D13-1 -> 0.070144166 | F14: =F13/E13-1 -> 0.11011105 | G14: 0.10148 | H14: 0.075 | I14: 0.07 | J14: 0.07 | K14: 0.065
A16: Warehouse Ancillary & Other Businesses | B16: 31626 | C16: 46474 | D16: 48693 | E16: 49969 | F16: 51170 | G16: =F16*(1+G17) -> 56362.732 | H16: =G16*(1+H17) -> 59180.868 | I16: =H16*(1+I17) -> 62139.912 | J16: =I16*(1+J17) -> 64936.208 | K16: =J16*(1+K17) -> 67858.337
A17: YoY growth % | C17: =C16/B16-1 -> 0.46948713 | D17: =D16/C16-1 -> 0.047747127 | E17: =E16/D16-1 -> 0.026204999 | F17: =F16/E16-1 -> 0.024034902 | G17: 0.10148 | H17: 0.05 | I17: 0.05 | J17: 0.045 | K17: 0.045
A20: TOTAL NET SALES | B20: =SUM(B7,B10,B13,B16) -> 192052 | C20: =SUM(C7,C10,C13,C16) -> 222730 | D20: =SUM(D7,D10,D13,D16) -> 237710 | E20: =SUM(E7,E10,E13,E16) -> 249625 | F20: =SUM(F7,F10,F13,F16) -> 269912 | G20: =SUM(G7,G10,G13,G16) -> 297302.67 | H20: =SUM(H7,H10,H13,H16) -> 316411.67 | I20: =SUM(I7,I10,I13,I16) -> 335484.43 | ... K20: =SUM(K7,K10,K13,K16) -> 375094.89
A21: Total Net Sales YoY growth % | C21: =C20/B20-1 -> 0.15973799 | D21: =D20/C20-1 -> 0.067256319 | E21: =E20/D20-1 -> 0.050124101 | F21: =F20/E20-1 -> 0.081269905 | G21: =G20/F20-1 -> 0.10148 | H21: =H20/G20-1 -> 0.064274578 | I21: =I20/H20-1 -> 0.060278306 | J21: =J20/I20-1 -> 0.059398976 | K21: =K20/J20-1 -> 0.055380892
A22: Memo: FY2026A actual net sales (Aug 2026 sales release, pre-audit) | G22: 297300
A23: Model vs. actual variance (2026E) | G23: =G20/G22-1 -> 8.9800202e-06
A25: Membership Fees | B25: 3877 | C25: 4224 | D25: 4580 | E25: 4828 | F25: 5323 | G25: =F25*(1+G26) -> 5881.915 | H25: =G25*(1+H26) -> 6293.649 | I25: =H25*(1+I26) -> 6734.2045 | J25: =I25*(1+J26) -> 7171.9278 | K25: =J25*(1+K26) -> 7638.1031
A26: YoY growth % (2021-25A) / Growth assumption (2026E-30E, blue) | C26: =C25/B25-1 -> 0.089502192 | D26: =D25/C25-1 -> 0.084280303 | E26: =E25/D25-1 -> 0.054148472 | F26: =F25/E25-1 -> 0.10252693 | G26: 0.105 | H26: 0.07 | I26: 0.07 | J26: 0.065 | K26: 0.065
A29: TOTAL REVENUE (Net Sales + Membership Fees) | B29: =B20+B25 -> 195929 | C29: =C20+C25 -> 226954 | D29: =D20+D25 -> 242290 | E29: =E20+E25 -> 254453 | F29: =F20+F25 -> 275235 | G29: =G20+G25 -> 303184.58 | H29: =H20+H25 -> 322705.32 | I29: =I20+I25 -> 342218.64 | ... K29: =K20+K25 -> 382732.99
A31: B. REVENUE BY GEOGRAPHIC SEGMENT (Total revenue basis, per 10-K segment footnote)
A32: ($ in millions) | B32: 2021A | C32: 2022A | D32: 2023A | E32: 2024A | F32: 2025A | G32: 2026E | H32: 2027E | I32: 2028E | J32: 2029E | K32: 2030E
A33: United States — % of total revenue | B33: =141398/195929 -> 0.72167979 | C33: =165294/226954 -> 0.72831499 | D33: =176630/242290 -> 0.72900244 | E33: =0.729 -> 0.729 | F33: 0.722 | G33: 0.7205 | H33: 0.719 | I33: 0.7175 | J33: 0.716 | K33: 0.7145
A34: United States | B34: =B29*B33 -> 141398 | C34: =C29*C33 -> 165294 | D34: =D29*D33 -> 176630 | E34: =E29*E33 -> 185496.24 | F34: =F29*F33 -> 198719.67 | G34: =G29*G33 -> 218444.49 | H34: =H29*H33 -> 232025.13 | I34: =I29*I33 -> 245541.87 | ... K34: =K29*K33 -> 273462.72
A35: YoY growth % | C35: =C34/B34-1 -> 0.16899815 | D35: =D34/C34-1 -> 0.068580832 | E35: =E34/D34-1 -> 0.050196665 | F35: =F34/E34-1 -> 0.071286799 | G35: =G34/F34-1 -> 0.099259541 | H35: =H34/G34-1 -> 0.062169723 | I35: =I34/H34-1 -> 0.058255525 | J35: =J34/I34-1 -> 0.057294192 | K35: =K34/J34-1 -> 0.053359767
A37: Canada — % of total revenue | B37: =27298/195929 -> 0.13932598 | C37: =31675/226954 -> 0.13956573 | D37: =33056/242290 -> 0.13643155 | E37: =0.1364 -> 0.1364 | F37: 0.137 | G37: 0.1372 | H37: 0.1374 | I37: 0.1376 | J37: 0.1378 | K37: 0.138
A38: Canada | B38: =B29*B37 -> 27298 | C38: =C29*C37 -> 31675 | D38: =D29*D37 -> 33056 | E38: =E29*E37 -> 34707.389 | F38: =F29*F37 -> 37707.195 | G38: =G29*G37 -> 41596.925 | H38: =H29*H37 -> 44339.711 | I38: =I29*I37 -> 47089.285 | ... K38: =K29*K37 -> 52817.153
A39: YoY growth % | C39: =C38/B38-1 -> 0.16034142 | D39: =D38/C38-1 -> 0.043599053 | E39: =E38/D38-1 -> 0.049957321 | F39: =F38/E38-1 -> 0.08643133 | G39: =G38/F38-1 -> 0.10315618 | H39: =H38/G38-1 -> 0.065937237 | I39: =I38/H38-1 -> 0.062011528 | J39: =J38/I38-1 -> 0.061049178 | K39: =K38/J38-1 -> 0.057103192
A41: Other International — % of total revenue | B41: =27233/195929 -> 0.13899423 | C41: =29985/226954 -> 0.13211928 | D41: =32604/242290 -> 0.13456602 | E41: =0.1346 -> 0.1346 | F41: 0.141 | G41: 0.1423 | H41: 0.1436 | I41: 0.1449 | J41: 0.1462 | K41: 0.1475
A42: Other International | B42: =B29*B41 -> 27233 | C42: =C29*C41 -> 29985 | D42: =D29*D41 -> 32604 | E42: =E29*E41 -> 34249.374 | F42: =F29*F41 -> 38808.135 | G42: =G29*G41 -> 43143.166 | H42: =H29*H41 -> 46340.484 | I42: =I29*I41 -> 49587.481 | ... K42: =K29*K41 -> 56453.117
A43: YoY growth % | C43: =C42/B42-1 -> 0.10105387 | D43: =D42/C42-1 -> 0.087343672 | E43: =E42/D42-1 -> 0.050465397 | F43: =F42/E42-1 -> 0.13310495 | G43: =G42/F42-1 -> 0.11170419 | H43: =H42/G42-1 -> 0.074109486 | I43: =I42/H42-1 -> 0.070068242 | J43: =J42/I42-1 -> 0.069014797 | K43: =K42/J42-1 -> 0.064957222
A45: TOTAL REVENUE (Geography basis) | B45: =SUM(B34,B38,B42) -> 195929 | C45: =SUM(C34,C38,C42) -> 226954 | D45: =SUM(D34,D38,D42) -> 242290 | E45: =SUM(E34,E38,E42) -> 254453 | F45: =SUM(F34,F38,F42) -> 275235 | G45: =SUM(G34,G38,G42) -> 303184.58 | H45: =SUM(H34,H38,H42) -> 322705.32 | I45: =SUM(I34,I38,I42) -> 342218.64 | ... K45: =SUM(K34,K38,K42) -> 382732.99
A46: Check vs. Total Revenue (category basis) — should be exactly 0 by construction | B46: =B45-B29 -> 0 | C46: =C45-C29 -> 0 | D46: =D45-D29 -> 0 | E46: =E45-E29 -> 0 | F46: =F45-F29 -> 0 | G46: =G45-G29 -> 0 | H46: =H45-H29 -> 0 | I46: =I45-I29 -> 0 | ... K46: =K45-K29 -> 0
A47: Memo: shares (US/Canada/Other Intl) must sum to 100% — check | B47: =B33+B37+B41-1 -> 0 | C47: =C33+C37+C41-1 -> 0 | D47: =D33+D37+D41-1 -> 0 | E47: =E33+E37+E41-1 -> 0 | F47: =F33+F37+F41-1 -> 0 | G47: =G33+G37+G41-1 -> 0 | H47: =H33+H37+H41-1 -> 0 | I47: =I33+I37+I41-1 -> 0 | ... K47: =K33+K37+K41-1 -> 0

Sheet Income Statement
A1: Costco Wholesale Corporation — Income Statement
A2: Task 2: Financial Modeling | FY2021A-FY2025A: exact, Costco 10-K filings (SEC EDGAR). FY2026E-FY2030E: analyst projections.
A3: All figures in US$ millions except per-share and ratio data, unless noted. Fiscal year ends ~Aug 31 (52/53-week fiscal year).
A5: ($ in millions) | B5: 2021A | C5: 2022A | D5: 2023A | E5: 2024A | F5: 2025A | G5: 2026E | H5: 2027E | I5: 2028E | J5: 2029E | K5: 2030E
A6: REVENUE
A7: Net sales | B7: ='Revenue Model'!B20 -> 192052 | C7: ='Revenue Model'!C20 -> 222730 | D7: ='Revenue Model'!D20 -> 237710 | E7: ='Revenue Model'!E20 -> 249625 | F7: ='Revenue Model'!F20 -> 269912 | G7: ='Revenue Model'!G20 -> 297302.67 | H7: ='Revenue Model'!H20 -> 316411.67 | I7: ='Revenue Model'!I20 -> 335484.43 | ... K7: ='Revenue Model'!K20 -> 375094.89
A8: YoY growth % | C8: =C7/B7-1 -> 0.15973799 | D8: =D7/C7-1 -> 0.067256319 | E8: =E7/D7-1 -> 0.050124101 | F8: =F7/E7-1 -> 0.081269905 | G8: =G7/F7-1 -> 0.10148 | H8: =H7/G7-1 -> 0.064274578 | I8: =I7/H7-1 -> 0.060278306 | J8: =J7/I7-1 -> 0.059398976 | K8: =K7/J7-1 -> 0.055380892
A9: Membership fees | B9: ='Revenue Model'!B25 -> 3877 | C9: ='Revenue Model'!C25 -> 4224 | D9: ='Revenue Model'!D25 -> 4580 | E9: ='Revenue Model'!E25 -> 4828 | F9: ='Revenue Model'!F25 -> 5323 | G9: ='Revenue Model'!G25 -> 5881.915 | H9: ='Revenue Model'!H25 -> 6293.649 | I9: ='Revenue Model'!I25 -> 6734.2045 | ... K9: ='Revenue Model'!K25 -> 7638.1031
A10: Total revenue | B10: =B7+B9 -> 195929 | C10: =C7+C9 -> 226954 | D10: =D7+D9 -> 242290 | E10: =E7+E9 -> 254453 | F10: =F7+F9 -> 275235 | G10: =G7+G9 -> 303184.58 | H10: =H7+H9 -> 322705.32 | I10: =I7+I9 -> 342218.64 | ... K10: =K7+K9 -> 382732.99
A11: YoY growth % | C11: =C10/B10-1 -> 0.15834818 | D11: =D10/C10-1 -> 0.067573165 | E11: =E10/D10-1 -> 0.050200173 | F11: =F10/E10-1 -> 0.081673236 | G11: =G10/F10-1 -> 0.10154808 | H11: =H10/G10-1 -> 0.064385654 | I11: =I10/H10-1 -> 0.060467906 | J11: =J10/I10-1 -> 0.059509193 | K11: =K10/J10-1 -> 0.055571159
A13: OPERATING EXPENSES
A14: Merchandise costs | B14: 170684 | C14: 199382 | D14: 212586 | E14: 222358 | F14: 239886 | G14: =G7*(1-G15) -> 264361.53 | H14: =H7*(1-H15) -> 281448.18 | I14: =I7*(1-I15) -> 298312.76 | J14: =J7*(1-J15) -> 315961.15 | K14: =K7*(1-K15) -> 333384.34
A15: Gross margin % (of net sales) | B15: =1-B14/B7 -> 0.11126153 | C15: =1-C14/C7 -> 0.10482647 | D15: =1-D14/D7 -> 0.10569181 | E15: =1-E14/E7 -> 0.10923185 | F15: =1-F14/F7 -> 0.11124366 | G15: 0.1108 | H15: 0.1105 | I15: 0.1108 | J15: 0.111 | K15: 0.1112
A17: Gross margin (Net sales - Merchandise costs) | B17: =B7-B14 -> 21368 | C17: =C7-C14 -> 23348 | D17: =D7-D14 -> 25124 | E17: =E7-E14 -> 27267 | F17: =F7-F14 -> 30026 | G17: =G7-G14 -> 32941.136 | H17: =H7-H14 -> 34963.49 | I17: =I7-I14 -> 37171.675 | ... K17: =K7-K14 -> 41710.552
A19: Selling, general and administrative | B19: 18537 | C19: 19779 | D19: 21590 | E19: 22810 | F19: 24966 | G19: =G7*G20 -> 27500.497 | H19: =H7*H20 -> 29109.874 | I19: =I7*I20 -> 30797.471 | J19: =J7*J20 -> 32520.186 | K19: =K7*K20 -> 34208.654
A20: % of net sales | B20: =B19/B7 -> 0.096520734 | C20: =C19/C7 -> 0.088802586 | D20: =D19/D7 -> 0.090824955 | E20: =E19/E7 -> 0.091377066 | F20: =F19/F7 -> 0.092496814 | G20: 0.0925 | H20: 0.092 | I20: 0.0918 | J20: 0.0915 | K20: 0.0912
A23: OPERATING INCOME | B23: =B17+B9-B19 -> 6708 | C23: =C17+C9-C19 -> 7793 | D23: =D17+D9-D19 -> 8114 | E23: =E17+E9-E19 -> 9285 | F23: =F17+F9-F19 -> 10383 | G23: =G17+G9-G19 -> 11322.554 | H23: =H17+H9-H19 -> 12147.265 | I23: =I17+I9-I19 -> 13108.409 | ... K23: =K17+K9-K19 -> 15140.001
A24: Operating margin % (of total revenue) | B24: =B23/B10 -> 0.034236892 | C24: =C23/C10 -> 0.034337355 | D24: =D23/D10 -> 0.033488794 | E24: =E23/E10 -> 0.036490039 | F24: =F23/F10 -> 0.037724127 | G24: =G23/G10 -> 0.037345414 | H24: =H23/H10 -> 0.037641973 | I24: =I23/I10 -> 0.038304193 | ... K24: =K23/K10 -> 0.039557606
A26: OTHER INCOME (EXPENSE)
A27: Interest expense | B27: -171 | C27: -158 | D27: -160 | E27: -169 | G27: -165 | H27: -160 | I27: -158 | J27: -155 | K27: -150
A28: Interest income and other, net | B28: 143 | C28: 205 | D28: 533 | E28: 624 | F28: 435 | G28: 550 | H28: 500 | I28: 480 | J28: 470 | K28: 460
A29: INCOME BEFORE INCOME TAXES | B29: =B23+B27+B28 -> 6680 | C29: =C23+C27+C28 -> 7840 | D29: =D23+D27+D28 -> 8487 | E29: =E23+E27+E28 -> 9740 | F29: =F23+F27+F28 -> 10818 | G29: =G23+G27+G28 -> 11707.554 | H29: =H23+H27+H28 -> 12487.265 | I29: =I23+I27+I28 -> 13430.409 | ... K29: =K23+K27+K28 -> 15450.001
A30: Provision for income taxes | B30: 1601 | C30: 1925 | D30: 2195 | E30: 2373 | F30: 2719 | G30: =G29*G31 -> 2903.4734 | H30: =H29*H31 -> 3084.3545 | I30: =I29*I31 -> 3303.8805 | J30: =J29*J31 -> 3546.6949 | K30: =K29*K31 -> 3785.2502
A31: Effective tax rate | B31: =B30/B29 -> 0.23967066 | C31: =C30/C29 -> 0.24553571 | D31: =D30/D29 -> 0.25863085 | E31: =E30/E29 -> 0.2436345 | F31: =F30/F29 -> 0.25134036 | G31: 0.248 | H31: 0.247 | I31: 0.246 | J31: 0.246 | K31: 0.245
A33: Net income including noncontrolling interests | B33: =B29-B30 -> 5079 | C33: =C29-C30 -> 5915 | D33: =D29-D30 -> 6292 | E33: =E29-E30 -> 7367 | F33: =F29-F30 -> 8099 | G33: =G29-G30 -> 8804.0805 | H33: =H29-H30 -> 9402.9106 | I33: =I29-I30 -> 10126.528 | ... K33: =K29-K30 -> 11664.751
A34: Net income attributable to noncontrolling interests | B34: -72 | C34: -71 | D34: 0 | E34: 0 | F34: 0 | G34: 0 | H34: 0 | I34: 0 | J34: 0 | K34: 0
A35: NET INCOME ATTRIBUTABLE TO COSTCO | B35: =B33+B34 -> 5007 | C35: =C33+C34 -> 5844 | D35: =D33+D34 -> 6292 | E35: =E33+E34 -> 7367 | F35: =F33+F34 -> 8099 | G35: =G33+G34 -> 8804.0805 | H35: =H33+H34 -> 9402.9106 | I35: =I33+I34 -> 10126.528 | ... K35: =K33+K34 -> 11664.751
A36: Net margin % (of total revenue) | B36: =B35/B10 -> 0.025555176 | C36: =C35/C10 -> 0.025749711 | D36: =D35/D10 -> 0.02596888 | E36: =E35/E10 -> 0.028952302 | F36: =F35/F10 -> 0.029425763 | G36: =G35/G10 -> 0.029038681 | H36: =H35/H10 -> 0.029137761 | I36: =I35/I10 -> 0.029590814 | ... K36: =K35/K10 -> 0.030477515
A38: SHARES & PER-SHARE DATA
A39: Diluted weighted-average shares (000s) | B39: 444346 | C39: 444757 | D39: 444452 | E39: 445044 | F39: 444865 | G39: 444000 | H39: 442500 | I39: 441000 | J39: 439500 | K39: 438000
A40: Diluted EPS | B40: =B35*1000/B39 -> 11.268246 | C40: =C35*1000/C39 -> 13.139759 | D40: =D35*1000/D39 -> 14.156759 | E40: =E35*1000/E39 -> 16.553419 | F40: =F35*1000/F39 -> 18.205523 | G40: =G35*1000/G39 -> 19.82901 | H40: =H35*1000/H39 -> 21.249515 | I40: =I35*1000/I39 -> 22.962649 | ... K40: =K35*1000/K39 -> 26.631851
A41: Diluted EPS YoY growth % | C41: =C40/B40-1 -> 0.16608739 | D41: =D40/C40-1 -> 0.077398667 | E41: =E40/D40-1 -> 0.1692944 | F41: =F40/E40-1 -> 0.099804369 | G41: =G40/F40-1 -> 0.089175527 | H41: =H40/G40-1 -> 0.071637728 | I41: =I40/H40-1 -> 0.080619888 | J41: =J40/I40-1 -> 0.077157501 | K41: =K40/J40-1 -> 0.076713491

Sheet Cash Flow Statement
A1: Costco Wholesale Corporation — Cash Flow Statement
A2: Task 2: Financial Modeling | Operating/Investing cash flow FY2024A-25A exact (10-K); FY2021A-23A D&A and CapEx exact (10-K segment note); other lines estimated where noted.
A3: All figures in US$ millions except per-share and ratio data, unless noted. Fiscal year ends ~Aug 31 (52/53-week fiscal year).
A5: ($ in millions) | B5: 2021A | C5: 2022A | D5: 2023A | E5: 2024A | F5: 2025A | G5: 2026E | H5: 2027E | I5: 2028E | J5: 2029E | K5: 2030E
A6: OPERATING ACTIVITIES
A7: Net income attributable to Costco | B7: ='Income Statement'!B35 -> 5007 | C7: ='Income Statement'!C35 -> 5844 | D7: ='Income Statement'!D35 -> 6292 | E7: ='Income Statement'!E35 -> 7367 | F7: ='Income Statement'!F35 -> 8099 | G7: ='Income Statement'!G35 -> 8804.0805 | H7: ='Income Statement'!H35 -> 9402.9106 | I7: ='Income Statement'!I35 -> 10126.528 | ... K7: ='Income Statement'!K35 -> 11664.751
A8: Depreciation and amortization | B8: 1781 | C8: 1900 | D8: 2077 | E8: 2188 | F8: 2367 | G8: 2570 | H8: 2790 | I8: 3010 | J8: 3230 | K8: 3450
A9: Stock-based compensation (est.) | B9: 530 | C9: 570 | D9: 620 | E9: 670 | F9: 720 | G9: 770 | H9: 820 | I9: 870 | J9: 920 | K9: 970
A10: Changes in working capital (net) | B10: 420 | C10: 380 | D10: -180 | E10: 310 | F10: 260 | G10: 200 | H10: 220 | I10: 240 | J10: 250 | K10: 260
A11: CASH FROM OPERATIONS | B11: =SUM(B7:B10) -> 7738 | C11: =SUM(C7:C10) -> 8694 | D11: =SUM(D7:D10) -> 8809 | E11: 11339 | F11: 13335 | G11: =SUM(G7:G10) -> 12344.081 | H11: =SUM(H7:H10) -> 13232.911 | I11: =SUM(I7:I10) -> 14246.528 | J11: =SUM(J7:J10) -> 15270.764 | K11: =SUM(K7:K10) -> 16344.751
A12: CFO margin % (of total revenue) | B12: =B11/'Income Statement'!B10 -> 0.039493898 | C12: =C11/'Income Statement'!C10 -> 0.038307322 | D12: =D11/'Income Statement'!D10 -> 0.036357258 | E12: =E11/'Income Statement'!E10 -> 0.044562257 | F12: =F11/'Income Statement'!F10 -> 0.048449507 | G12: =G11/'Income Statement'!G10 -> 0.040714737 | H12: =H11/'Income Statement'!H10 -> 0.041006174 | I12: =I11/'Income Statement'!I10 -> 0.041629901 | ... K12: =K11/'Income Statement'!K10 -> 0.042705361
A14: INVESTING ACTIVITIES
A15: Capital expenditures | B15: -3588 | C15: -3891 | D15: -4323 | E15: -4409 | F15: -5311 | G15: -6250 | H15: -6600 | I15: -6900 | J15: -7150 | K15: -7400
A16: Other investing activities (net) | B16: 0 | C16: 0 | D16: 0 | E16: 0 | F16: 0 | G16: 0 | H16: 0 | I16: 0 | J16: 0 | K16: 0
A17: CASH FROM INVESTING | B17: =B15+B16 -> -3588 | C17: =C15+C16 -> -3891 | D17: =D15+D16 -> -4323 | E17: =E15+E16 -> -4409 | F17: =F15+F16 -> -5311 | G17: =G15+G16 -> -6250 | H17: =H15+H16 -> -6600 | I17: =I15+I16 -> -6900 | ... K17: =K15+K16 -> -7400
A19: FREE CASH FLOW (CFO + CapEx) | B19: =B11+B15 -> 4150 | C19: =C11+C15 -> 4803 | D19: =D11+D15 -> 4486 | E19: =E11+E15 -> 6930 | F19: =F11+F15 -> 8024 | G19: =G11+G15 -> 6094.0805 | H19: =H11+H15 -> 6632.9106 | I19: =I11+I15 -> 7346.5282 | ... K19: =K11+K15 -> 8944.7507
A20: FCF margin % (of total revenue) | B20: =B19/'Income Statement'!B10 -> 0.021181142 | C20: =C19/'Income Statement'!C10 -> 0.021162879 | D20: =D19/'Income Statement'!D10 -> 0.018515003 | E20: =E19/'Income Statement'!E10 -> 0.027234892 | F20: =F19/'Income Statement'!F10 -> 0.029153269 | G20: =G19/'Income Statement'!G10 -> 0.020100232 | H20: =H19/'Income Statement'!H10 -> 0.020554079 | I20: =I19/'Income Statement'!I10 -> 0.021467353 | ... K20: =K19/'Income Statement'!K10 -> 0.023370733
A22: FINANCING ACTIVITIES
A23: Debt issuance / (repayment), net | B23: -800 | C23: -700 | D23: -700 | E23: -1077 | F23: -103 | G23: -100 | H23: -100 | I23: -100 | J23: -100 | K23: -100
A24: Share repurchases | B24: -250 | C24: -250 | D24: -250 | E24: -350 | F24: -903 | G24: -900 | H24: -900 | I24: -900 | J24: -900 | K24: -900
A25: Dividends paid (regular + special) | B25: -1440 | C25: -1622 | D25: -1877 | E25: -8589 | F25: -2183 | G25: -2450 | H25: -2650 | I25: -2850 | J25: -3050 | K25: -3250
A26: Other financing activities (net) | B26: -120 | C26: -120 | D26: -120 | E26: -120 | F26: -120 | G26: -130 | H26: -130 | I26: -130 | J26: -130 | K26: -130
A27: CASH FROM FINANCING | B27: =SUM(B23:B26) -> -2610 | C27: =SUM(C23:C26) -> -2692 | D27: =SUM(D23:D26) -> -2947 | E27: =SUM(E23:E26) -> -10136 | F27: =SUM(F23:F26) -> -3309 | G27: =SUM(G23:G26) -> -3580 | H27: =SUM(H23:H26) -> -3780 | I27: =SUM(I23:I26) -> -3980 | ... K27: =SUM(K23:K26) -> -4380
A29: NET CHANGE IN CASH | B29: =B11+B17+B27 -> 1540 | C29: =C11+C17+C27 -> 2111 | D29: =D11+D17+D27 -> 1539 | E29: =E11+E17+E27 -> -3206 | F29: =F11+F17+F27 -> 4715 | G29: =G11+G17+G27 -> 2514.0805 | H29: =H11+H17+H27 -> 2852.9106 | I29: =I11+I17+I27 -> 3366.5282 | ... K29: =K11+K17+K27 -> 4564.7507

Sheet Balance Sheet
A1: Costco Wholesale Corporation — Balance Sheet
A2: Task 2: Financial Modeling | FY2021A-23A: exact, Costco 10-K (SEC EDGAR). FY2024A-25A: key totals exact; sub-line detail allocated proportionally where noted.
A3: All figures in US$ millions except per-share and ratio data, unless noted. Fiscal year ends ~Aug 31 (52/53-week fiscal year).
A5: ($ in millions) | B5: 2021A | C5: 2022A | D5: 2023A | E5: 2024A | F5: 2025A | G5: 2026E | H5: 2027E | I5: 2028E | J5: 2029E | K5: 2030E
A6: ASSETS
A7: Current Assets:
A8: Cash & cash equivalents + short-term investments (plug — see memo row below) | B8: =B28+B31-(B9+B10+B11+B14+B15) -> 12175 | C8: =C28+C31-(C9+C10+C11+C14+C15) -> 11049 | D8: =D28+D31-(D9+D10+D11+D14+D15) -> 15234 | E8: =E28+E31-(E9+E10+E11+E14+E15) -> 7945 | F8: =F28+F31-(F9+F10+F11+F14+F15) -> 11754 | G8: =G28+G31-(G9+G10+G11+G14+G15) -> 14176.081 | H8: =H28+H31-(H9+H10+H11+H14+H15) -> 16748.991 | I8: =I28+I31-(I9+I10+I11+I14+I15) -> 19755.519 | ... K8: =K28+K31-(K9+K10+K11+K14+K15) -> 27341.034
A9: Receivables, net | B9: 1803 | C9: 2241 | D9: 2285 | E9: 2519 | F9: 2670 | G9: 2850 | H9: 3020 | I9: 3200 | J9: 3390 | K9: 3580
A10: Merchandise inventories | B10: 14215 | C10: 17907 | D10: 16651 | E10: 18647 | F10: 18120 | G10: 19400 | H10: 20500 | I10: 21600 | J10: 22700 | K10: 23800
A11: Other current assets | B11: 1312 | C11: 1499 | D11: 1709 | E11: 1750 | F11: 1780 | G11: 1900 | H11: 2000 | I11: 2100 | J11: 2200 | K11: 2300
A12: TOTAL CURRENT ASSETS | B12: =SUM(B8:B11) -> 29505 | C12: =SUM(C8:C11) -> 32696 | D12: =SUM(D8:D11) -> 35879 | E12: =SUM(E8:E11) -> 30861 | F12: =SUM(F8:F11) -> 34324 | G12: =SUM(G8:G11) -> 38326.081 | H12: =SUM(H8:H11) -> 42268.991 | I12: =SUM(I8:I11) -> 46655.519 | ... K12: =SUM(K8:K11) -> 57021.034
A14: Property and equipment, net | B14: 23492 | C14: 24646 | D14: 26684 | E14: 29294 | F14: 31908 | G14: =F14-'Cash Flow Statement'!G15-'Cash Flow Statement'!G8 -> 35588 | H14: =G14-'Cash Flow Statement'!H15-'Cash Flow Statement'!H8 -> 39398 | I14: =H14-'Cash Flow Statement'!I15-'Cash Flow Statement'!I8 -> 43288 | J14: =I14-'Cash Flow Statement'!J15-'Cash Flow Statement'!J8 -> 47208 | K14: =J14-'Cash Flow Statement'!K15-'Cash Flow Statement'!K8 -> 51158
A15: Operating lease ROU + other long-term assets | B15: 6271 | C15: 6824 | D15: 6431 | E15: 8895 | F15: 10188 | G15: 10800 | H15: 11400 | I15: 12000 | J15: 12600 | K15: 13200
A16: TOTAL ASSETS | B16: =B12+B14+B15 -> 59268 | C16: =C12+C14+C15 -> 64166 | D16: =D12+D14+D15 -> 68994 | E16: =E12+E14+E15 -> 69050 | F16: =F12+F14+F15 -> 76420 | G16: =G12+G14+G15 -> 84714.081 | H16: =H12+H14+H15 -> 93066.991 | I16: =I12+I14+I15 -> 101943.52 | ... K16: =K12+K14+K15 -> 121379.03
A17: Memo: Total assets per Yahoo Finance / 10-K aggregates | B17: 64166 | C17: 64166 | D17: 68994 | E17: 69830 | F17: 77100
A19: LIABILITIES
A20: Current Liabilities:
A21: Accounts payable | B21: 16278 | C21: 17848 | D21: 17483 | E21: 18500 | F21: 19700 | G21: 21000 | H21: 22300 | I21: 23600 | J21: 24900 | K21: 26200
A22: Accrued liabilities (salaries, member rewards, deferred fees, other) | B22: 12364 | C22: 14077 | D22: 15019 | E22: 15800 | F22: 16600 | G22: 17600 | H22: 18700 | I22: 19800 | J22: 20900 | K22: 22000
A23: Current portion of long-term debt | B23: 799 | C23: 73 | D23: 1081 | E23: 130 | F23: 60 | G23: 500 | H23: 500 | I23: 500 | J23: 500 | K23: 500
A24: TOTAL CURRENT LIABILITIES | B24: =SUM(B21:B23) -> 29441 | C24: =SUM(C21:C23) -> 31998 | D24: =SUM(D21:D23) -> 33583 | E24: =SUM(E21:E23) -> 34430 | F24: =SUM(F21:F23) -> 36360 | G24: =SUM(G21:G23) -> 39100 | H24: =SUM(H21:H23) -> 41500 | I24: =SUM(I21:I23) -> 43900 | ... K24: =SUM(K21:K23) -> 48700
A26: Long-term debt, excluding current portion | B26: 6692 | C26: 6484 | D26: 5377 | E26: 5800 | F26: 5500 | G26: =F26+'Cash Flow Statement'!G23 -> 5400 | H26: =G26+'Cash Flow Statement'!H23 -> 5300 | I26: =H26+'Cash Flow Statement'!I23 -> 5200 | J26: =I26+'Cash Flow Statement'!J23 -> 5100 | K26: =J26+'Cash Flow Statement'!K23 -> 5000
A27: Other long-term liabilities (incl. operating leases) | B27: 5057 | C27: 5037 | D27: 4976 | E27: 5200 | F27: 5400 | G27: 5600 | H27: 5800 | I27: 6000 | J27: 6200 | K27: 6400
A28: TOTAL LIABILITIES | B28: =B24+B26+B27 -> 41190 | C28: =C24+C26+C27 -> 43519 | D28: =D24+D26+D27 -> 43936 | E28: =E24+E26+E27 -> 45430 | F28: =F24+F26+F27 -> 47260 | G28: =G24+G26+G27 -> 50100 | H28: =H24+H26+H27 -> 52600 | I28: =I24+I26+I27 -> 55100 | ... K28: =K24+K26+K27 -> 60100
A30: EQUITY
A31: Total Costco stockholders' equity | B31: 18078 | C31: 20647 | D31: 25058 | E31: 23620 | F31: 29160 | G31: =F31+'Income Statement'!G35+'Cash Flow Statement'!G25+'Cash Flow Statement'!G24 -> 34614.081 | H31: =G31+'Income Statement'!H35+'Cash Flow Statement'!H25+'Cash Flow Statement'!H24 -> 40466.991 | I31: =H31+'Income Statement'!I35+'Cash Flow Statement'!I25+'Cash Flow Statement'!I24 -> 46843.519 | J31: =I31+'Income Statement'!J35+'Cash Flow Statement'!J25+'Cash Flow Statement'!J24 -> 53764.283 | K31: =J31+'Income Statement'!K35+'Cash Flow Statement'!K25+'Cash Flow Statement'!K24 -> 61279.034
A32: TOTAL LIABILITIES + EQUITY | B32: =B28+B31 -> 59268 | C32: =C28+C31 -> 64166 | D32: =D28+D31 -> 68994 | E32: =E28+E31 -> 69050 | F32: =F28+F31 -> 76420 | G32: =G28+G31 -> 84714.081 | H32: =H28+H31 -> 93066.991 | I32: =I28+I31 -> 101943.52 | ... K32: =K28+K31 -> 121379.03
A33: BALANCE CHECK (Total Assets - Total Liab&Equity, should = 0) | B33: =B16-B32 -> 0 | C33: =C16-C32 -> 0 | D33: =D16-D32 -> 0 | E33: =E16-E32 -> 0 | F33: =F16-F32 -> 0 | G33: =G16-G32 -> 0 | H33: =H16-H32 -> 0 | I33: =I16-I32 -> 0 | ... K33: =K16-K32 -> 0
A34: Memo: Cash & ST investments per 10-K / press release (actual, for comparison) | B34: 12175 | C34: 11049 | D34: 15234 | E34: 11144 | F34: 15284
A35: Plug cash vs. actual cash, variance ($mm) | B35: =B8-B34 -> 0 | C35: =C8-C34 -> 0 | D35: =D8-D34 -> 0 | E35: =E8-E34 -> -3199 | F35: =F8-F34 -> -3530
A37: KEY BALANCE SHEET RATIOS
A38: Current ratio (Current Assets / Current Liabilities) | B38: =B12/B24 -> 1.0021738 | C38: =C12/C24 -> 1.0218139 | D38: =D12/D24 -> 1.0683679 | E38: =E12/E24 -> 0.8963404 | F38: =F12/F24 -> 0.9440044 | G38: =G12/G24 -> 0.98020666 | H38: =H12/H24 -> 1.0185299 | I38: =I12/I24 -> 1.0627681 | ... K38: =K12/K24 -> 1.1708631
A39: Debt-to-equity (Total debt / Total equity) | B39: =(B26+B23)/B31 -> 0.41437106 | C39: =(C26+C23)/C31 -> 0.3175764 | D39: =(D26+D23)/D31 -> 0.25772208 | E39: =(E26+E23)/E31 -> 0.25105843 | F39: =(F26+F23)/F31 -> 0.19067215 | G39: =(G26+G23)/G31 -> 0.17045087 | H39: =(H26+H23)/H31 -> 0.14332669 | I39: =(I26+I23)/I31 -> 0.12168172 | ... K39: =(K26+K23)/K31 -> 0.089753373
A40: Return on equity (Net income / Total equity) | B40: ='Income Statement'!B35/B31 -> 0.27696648 | C40: ='Income Statement'!C35/C31 -> 0.28304354 | D40: ='Income Statement'!D35/D31 -> 0.25109745 | E40: ='Income Statement'!E35/E31 -> 0.3118967 | F40: ='Income Statement'!F35/F31 -> 0.27774348 | G40: ='Income Statement'!G35/G31 -> 0.25434969 | H40: ='Income Statement'!H35/H31 -> 0.23236001 | I40: ='Income Statement'!I35/I31 -> 0.21617778 | ... K40: ='Income Statement'!K35/K31 -> 0.19035468

Sheet Scenarios
A1: Costco Wholesale Corporation — Bull / Base / Bear Scenarios
A2: Task 2: Financial Modeling | 5-year cumulative view, FY2026E-FY2030E terminal year (2030E) shown
A5: ASSUMPTIONS | B5: BULL | C5: BASE | D5: BEAR
A6: Revenue CAGR (FY2025A-FY2030E) | B6: 0.095 | C6: 0.075 | D6: 0.055
A7: Gross margin, FY2030E | B7: 0.114 | C7: 0.1112 | D7: 0.108
A8: SG&A % of net sales, FY2030E | B8: 0.0895 | C8: 0.0912 | D8: 0.094
A9: Operating margin, FY2030E (derived)
A10: CapEx as % of net sales, FY2030E | B10: 0.0215 | C10: 0.023 | D10: 0.025
A11: Effective tax rate, FY2030E | B11: 0.24 | C11: 0.245 | D11: 0.255
A12: Diluted share count reduction, cumulative FY26-30 | B12: -0.02 | C12: -0.013 | D12: -0.005
A14: Scenario rationale:
A15: Bull case:
A16: Executive-membership penetration keeps climbing, China expansion accelerates beyond current cautious pace, digital/delivery (DoorDash/Uber Eats partnerships) drives outsized comp growth, and gross margin expands modestly as fresh-food/co-branded-card mix improves — consistent with the top end of sell-side price targets (UBS $1,275, TD Cowen $1,175) referenced in Task 1 research.
A18: Base case:
A19: Trends continue at roughly the FY2025A run-rate: high-single-digit revenue growth, flat-to-slightly-improving gross margin, continued SG&A leverage, and CapEx in line with management's disclosed $6.0-6.5bn FY2026 guidance, scaling with warehouse growth thereafter.
A21: Bear case:
A22: Comparable-sales growth decelerates toward mid-single digits as U.S. warehouse saturation bites (a risk management itself has flagged per Task 1 research), Sam's Club fee-parity intensifies competition, tariff/input-cost pressure compresses gross margin, and the premium valuation multiple compresses alongside slower growth.
A24: OUTPUT SUMMARY (FY2030E terminal year, derived from assumptions above)
B25: BULL | C25: BASE | D25: BEAR
A26: FY2030E Net sales ($mm) | B26: ='Income Statement'!F7*(1+B6)^5 -> 424905.93 | C26: ='Income Statement'!F7*(1+C6)^5 -> 387493.58 | D26: ='Income Statement'!F7*(1+D6)^5 -> 352764.19
A27: FY2030E Membership fees ($mm, held at base-case growth path) | B27: ='Income Statement'!F9*(1+0.07)^5 -> 7465.7829 | C27: ='Income Statement'!F9*(1+0.07)^5 -> 7465.7829 | D27: ='Income Statement'!F9*(1+0.07)^5 -> 7465.7829
A28: FY2030E Gross margin ($mm) | B28: =B26*B7 -> 48439.276 | C28: =C26*C7 -> 43089.286 | D28: =D26*D7 -> 38098.532
A29: FY2030E SG&A ($mm) | B29: =B26*B8 -> 38029.08 | C29: =C26*C8 -> 35339.415 | D29: =D26*D8 -> 33159.834
A30: FY2030E Operating income ($mm) | B30: =B28+B27-B29 -> 17875.978 | C30: =C28+C27-C29 -> 15215.655 | D30: =D28+D27-D29 -> 12404.482
A31: FY2030E Operating margin % | B31: =B30/(B26+B27) -> 0.041344005 | C31: =C30/(C26+C27) -> 0.038524607 | D31: =D30/(D26+D27) -> 0.034434896
A32: FY2030E Net income ($mm, approx., excl. interest/other) | B32: =B30*(1-B11) -> 13585.743 | C32: =C30*(1-C11) -> 11487.819 | D32: =D30*(1-D11) -> 9241.3387
A33: FY2030E Diluted shares (mm) | B33: =('Income Statement'!F39/1000)*(1+B12) -> 435.9677 | C33: =('Income Statement'!F39/1000)*(1+C12) -> 439.08175 | D33: =('Income Statement'!F39/1000)*(1+D12) -> 442.64067
A34: FY2030E Diluted EPS | B34: =B32/B33 -> 31.16227 | C34: =C32/C33 -> 26.163281 | D34: =D32/D33 -> 20.877744
A35: FY2030E Free cash flow ($mm, approx.) | B35: =B32*1.28*(1-B10*1.6) -> 16791.544 | C35: =C32*1.28*(1-C10*1.6) -> 14163.286 | D35: =D32*1.28*(1-D10*1.6) -> 11355.757

Sheet DCF Inputs
A1: Costco Wholesale Corporation — DCF Inputs (Unlevered Free Cash Flow Build)
A2: Task 2: Financial Modeling | Feeds Task 3 Valuation Analysis. Projection years only (FY2026E-FY2030E); historicals shown for context.
A3: All figures in US$ millions except per-share and ratio data, unless noted. Fiscal year ends ~Aug 31 (52/53-week fiscal year).
A5: ($ in millions) | B5: 2021A | C5: 2022A | D5: 2023A | E5: 2024A | F5: 2025A | G5: 2026E | H5: 2027E | I5: 2028E | J5: 2029E | K5: 2030E
A6: EBIT (= Operating income) | B6: ='Income Statement'!B23 -> 6708 | C6: ='Income Statement'!C23 -> 7793 | D6: ='Income Statement'!D23 -> 8114 | E6: ='Income Statement'!E23 -> 9285 | F6: ='Income Statement'!F23 -> 10383 | G6: ='Income Statement'!G23 -> 11322.554 | H6: ='Income Statement'!H23 -> 12147.265 | I6: ='Income Statement'!I23 -> 13108.409 | ... K6: ='Income Statement'!K23 -> 15140.001
A7: Tax rate (effective, per Income Statement) | B7: ='Income Statement'!B30/'Income Statement'!B29 -> 0.23967066 | C7: ='Income Statement'!C30/'Income Statement'!C29 -> 0.24553571 | D7: ='Income Statement'!D30/'Income Statement'!D29 -> 0.25863085 | E7: ='Income Statement'!E30/'Income Statement'!E29 -> 0.2436345 | F7: ='Income Statement'!F30/'Income Statement'!F29 -> 0.25134036 | G7: ='Income Statement'!G30/'Income Statement'!G29 -> 0.248 | H7: ='Income Statement'!H30/'Income Statement'!H29 -> 0.247 | I7: ='Income Statement'!I30/'Income Statement'!I29 -> 0.246 | ... K7: ='Income Statement'!K30/'Income Statement'!K29 -> 0.245
A8: NOPAT (EBIT x (1 - tax rate)) | B8: =B6*(1-B7) -> 5100.2892 | C8: =C6*(1-C7) -> 5879.5402 | D8: =D6*(1-D7) -> 6015.4693 | E8: =E6*(1-E7) -> 7022.8537 | F8: =F6*(1-F7) -> 7773.3331 | G8: =G6*(1-G7) -> 8514.5605 | H8: =H6*(1-H7) -> 9146.8906 | I8: =I6*(1-I7) -> 9883.7402 | ... K8: =K6*(1-K7) -> 11430.701
A10: Add: Depreciation & amortization | B10: ='Cash Flow Statement'!B8 -> 1781 | C10: ='Cash Flow Statement'!C8 -> 1900 | D10: ='Cash Flow Statement'!D8 -> 2077 | E10: ='Cash Flow Statement'!E8 -> 2188 | F10: ='Cash Flow Statement'!F8 -> 2367 | G10: ='Cash Flow Statement'!G8 -> 2570 | H10: ='Cash Flow Statement'!H8 -> 2790 | I10: ='Cash Flow Statement'!I8 -> 3010 | ... K10: ='Cash Flow Statement'!K8 -> 3450
A11: Less: Capital expenditures | B11: ='Cash Flow Statement'!B15 -> -3588 | C11: ='Cash Flow Statement'!C15 -> -3891 | D11: ='Cash Flow Statement'!D15 -> -4323 | E11: ='Cash Flow Statement'!E15 -> -4409 | F11: ='Cash Flow Statement'!F15 -> -5311 | G11: ='Cash Flow Statement'!G15 -> -6250 | H11: ='Cash Flow Statement'!H15 -> -6600 | I11: ='Cash Flow Statement'!I15 -> -6900 | ... K11: ='Cash Flow Statement'!K15 -> -7400
A12: Less: Change in net working capital (est.) | B12: -420 | C12: -380 | D12: 180 | E12: -310 | F12: -260 | G12: -220 | H12: -230 | I12: -240 | J12: -250 | K12: -260
A14: UNLEVERED FREE CASH FLOW | B14: =B8+B10+B11+B12 -> 2873.2892 | C14: =C8+C10+C11+C12 -> 3508.5402 | D14: =D8+D10+D11+D12 -> 3949.4693 | E14: =E8+E10+E11+E12 -> 4491.8537 | F14: =F8+F10+F11+F12 -> 4569.3331 | G14: =G8+G10+G11+G12 -> 4614.5605 | H14: =H8+H10+H11+H12 -> 5106.8906 | I14: =I8+I10+I11+I12 -> 5753.7402 | ... K14: =K8+K10+K11+K12 -> 7220.7007
A15: UFCF margin % (of total revenue) | B15: =B14/'Income Statement'!B10 -> 0.014664951 | C15: =C14/'Income Statement'!C10 -> 0.015459257 | D15: =D14/'Income Statement'!D10 -> 0.016300587 | E15: =E14/'Income Statement'!E10 -> 0.01765298 | F15: =F14/'Income Statement'!F10 -> 0.01660157 | G15: =G14/'Income Statement'!G10 -> 0.015220301 | H15: =H14/'Income Statement'!H10 -> 0.015825244 | I15: =I14/'Income Statement'!I10 -> 0.016813053 | ... K15: =K14/'Income Statement'!K10 -> 0.018866157
A17: TERMINAL YEAR METRICS (FY2030E) — used in Task 3 Valuation
A18: FY2030E Revenue | B18: ='Income Statement'!K10 -> 382732.99
A19: FY2030E EBITDA (EBIT + D&A) | B19: =K6+K10 -> 18590.001
A20: FY2030E EBIT | B20: =K6 -> 15140.001
A21: FY2030E Unlevered FCF | B21: =K14 -> 7220.7007
A23: WACC BUILD-UP INPUTS (for Task 3)
A24: Risk-free rate (10-yr UST, approx.) | B24: 0.041
A25: Equity risk premium (approx., US large-cap) | B25: 0.045
A26: Beta (5-year monthly, per Yahoo Finance) | B26: 0.86
A27: Cost of equity (CAPM: Rf + Beta x ERP) | B27: =B24+B26*B25 -> 0.0797
A28: Pre-tax cost of debt (approx., per Senior Notes coupons) | B28: 0.033
A29: Effective tax rate (for after-tax cost of debt) | B29: 0.245
A30: Target Debt / Total Capital (approx., per market cap & total debt) | B30: 0.02
A32: WACC (= We x Ke + Wd x Kd x (1-t)) | B32: =(1-B30)*B27+B30*B28*(1-B29) -> 0.0786043

Sheet DCF Valuation
A1: Costco Wholesale Corporation — DCF Valuation
A2: Task 3: Valuation Analysis | 5-year explicit forecast (FY2026E-FY2030E) + Gordon Growth terminal value
A4: UNLEVERED FREE CASH FLOW (from DCF Inputs tab)
B5: 2026E | C5: 2027E | D5: 2028E | E5: 2029E | F5: 2030E
A6: Unlevered FCF ($mm) | B6: ='DCF Inputs'!G14 -> 4614.5605 | C6: ='DCF Inputs'!H14 -> 5106.8906 | D6: ='DCF Inputs'!I14 -> 5753.7402 | E6: ='DCF Inputs'!J14 -> 6463.2542 | F6: ='DCF Inputs'!K14 -> 7220.7007
A7: Discount period (years) | B7: 1 | C7: 2 | D7: 3 | E7: 4 | F7: 5
A9: WACC & TERMINAL GROWTH ASSUMPTIONS
A10: WACC (from DCF Inputs tab) | B10: ='DCF Inputs'!B32 -> 0.0786043
A11: Terminal (perpetuity) growth rate | B11: 0.025
A13: DISCOUNTED CASH FLOW CALCULATION
B14: 2026E | C14: 2027E | D14: 2028E | E14: 2029E | F14: 2030E
A15: Discount factor = 1/(1+WACC)^t | B15: =1/(1+$B$10)^B7 -> 0.92712406 | C15: =1/(1+$B$10)^C7 -> 0.85955903 | D15: =1/(1+$B$10)^D7 -> 0.79691786 | E15: =1/(1+$B$10)^E7 -> 0.73884172 | F15: =1/(1+$B$10)^F7 -> 0.68499794
A16: PV of Unlevered FCF ($mm) | B16: =B6*B15 -> 4278.2701 | C16: =C6*C15 -> 4389.6739 | D16: =D6*D15 -> 4585.2583 | E16: =E6*E15 -> 4775.3218 | F16: =F6*F15 -> 4946.1651
A17: Sum of PV of explicit-period FCF | B17: =SUM(B16:F16) -> 22974.689
A19: TERMINAL VALUE (Gordon Growth Method)
A20: Terminal Value = FCF(2030E) x (1+g) / (WACC-g) | B20: =F6*(1+B11)/(B10-B11) -> 138071.35
A21: PV of Terminal Value | B21: =B20*F15 -> 94578.592
A22: Memo: Terminal Value % of Enterprise Value (quality check) | B22: =B21/B25 -> 0.80455935
A24: ENTERPRISE VALUE TO EQUITY VALUE BRIDGE
A25: ENTERPRISE VALUE | B25: =B17+B21 -> 117553.28
A26: Less: Total debt (current + long-term) | B26: 8170
A27: Plus: Cash & cash equivalents + short-term investments | B27: 15284
A28: Net debt / (net cash) | B28: =B26-B27 -> -7114
A29: EQUITY VALUE | B29: =B25-B28 -> 124667.28
A31: PRICE PER SHARE
A32: Diluted shares outstanding (current, mm) | B32: 443.5
A33: DCF-IMPLIED PRICE PER SHARE | B33: =B29/B32 -> 281.09872
A34: Current share price (for reference) | B34: 895
A35: Implied upside / (downside) to DCF value | B35: =B33/B34-1 -> -0.68592322
A37: REVERSE DCF (What growth rate does the current price imply?)

Sheet DCF Sensitivity
A1: Costco Wholesale Corporation — DCF Sensitivity Analysis
A2: Task 3: Valuation Analysis | Implied price per share across WACC and terminal growth rate combinations
A4: TABLE 1: Implied Price per Share — WACC (rows) vs. Terminal Growth Rate (columns)
A6: WACC \ Terminal g | B6: 0.015 | C6: 0.02 | D6: 0.025 | E6: 0.03 | F6: 0.035
A7: 0.0636 | B7: =(SUMPRODUCT('DCF Valuation'!$B$6:$F$6,1/(1+0.0636)^'DCF Valuation'!$B$7:$F$7)+('DCF Valuation'!$F$6*(1+0.015)/(0.0636-0.015))/(1+0.0636)^5-'DCF Valuation'!$B$28)/'DCF Valuation'!$B$32 -> 319.95258 | C7: =(SUMPRODUCT('DCF Valuation'!$B$6:$F$6,1/(1+0.0636)^'DCF Valuation'!$B$7:$F$7)+('DCF Valuation'!$F$6*(1+0.02)/(0.0636-0.02))/(1+0.0636)^5-'DCF Valuation'!$B$28)/'DCF Valuation'!$B$32 -> 349.9732 | D7: =(SUMPRODUCT('DCF Valuation'!$B$6:$F$6,1/(1+0.0636)^'DCF Valuation'!$B$7:$F$7)+('DCF Valuation'!$F$6*(1+0.025)/(0.0636-0.025))/(1+0.0636)^5-'DCF Valuation'!$B$28)/'DCF Valuation'!$B$32 -> 387.77118 | E7: =(SUMPRODUCT('DCF Valuation'!$B$6:$F$6,1/(1+0.0636)^'DCF Valuation'!$B$7:$F$7)+('DCF Valuation'!$F$6*(1+0.03)/(0.0636-0.03))/(1+0.0636)^5-'DCF Valuation'!$B$28)/'DCF Valuation'!$B$32 -> 436.81856 | F7: =(SUMPRODUCT('DCF Valuation'!$B$6:$F$6,1/(1+0.0636)^'DCF Valuation'!$B$7:$F$7)+('DCF Valuation'!$F$6*(1+0.035)/(0.0636-0.035))/(1+0.0636)^5-'DCF Valuation'!$B$28)/'DCF Valuation'!$B$32 -> 503.01538
A8: 0.0686 | B8: =(SUMPRODUCT('DCF Valuation'!$B$6:$F$6,1/(1+0.0686)^'DCF Valuation'!$B$7:$F$7)+('DCF Valuation'!$F$6*(1+0.015)/(0.0686-0.015))/(1+0.0686)^5-'DCF Valuation'!$B$28)/'DCF Valuation'!$B$32 -> 290.61835 | C8: =(SUMPRODUCT('DCF Valuation'!$B$6:$F$6,1/(1+0.0686)^'DCF Valuation'!$B$7:$F$7)+('DCF Valuation'!$F$6*(1+0.02)/(0.0686-0.02))/(1+0.0686)^5-'DCF Valuation'!$B$28)/'DCF Valuation'!$B$32 -> 314.58427 | D8: =(SUMPRODUCT('DCF Valuation'!$B$6:$F$6,1/(1+0.0686)^'DCF Valuation'!$B$7:$F$7)+('DCF Valuation'!$F$6*(1+0.025)/(0.0686-0.025))/(1+0.0686)^5-'DCF Valuation'!$B$28)/'DCF Valuation'!$B$32 -> 344.04695 | E8: =(SUMPRODUCT('DCF Valuation'!$B$6:$F$6,1/(1+0.0686)^'DCF Valuation'!$B$7:$F$7)+('DCF Valuation'!$F$6*(1+0.03)/(0.0686-0.03))/(1+0.0686)^5-'DCF Valuation'!$B$28)/'DCF Valuation'!$B$32 -> 381.14245 | F8: =(SUMPRODUCT('DCF Valuation'!$B$6:$F$6,1/(1+0.0686)^'DCF Valuation'!$B$7:$F$7)+('DCF Valuation'!$F$6*(1+0.035)/(0.0686-0.035))/(1+0.0686)^5-'DCF Valuation'!$B$28)/'DCF Valuation'!$B$32 -> 429.27828
A9: 0.0736 | B9: =(SUMPRODUCT('DCF Valuation'!$B$6:$F$6,1/(1+0.0736)^'DCF Valuation'!$B$7:$F$7)+('DCF Valuation'!$F$6*(1+0.015)/(0.0736-0.015))/(1+0.0736)^5-'DCF Valuation'!$B$28)/'DCF Valuation'!$B$32 -> 266.30686 | C9: =(SUMPRODUCT('DCF Valuation'!$B$6:$F$6,1/(1+0.0736)^'DCF Valuation'!$B$7:$F$7)+('DCF Valuation'!$F$6*(1+0.02)/(0.0736-0.02))/(1+0.0736)^5-'DCF Valuation'!$B$28)/'DCF Valuation'!$B$32 -> 285.81533 | D9: =(SUMPRODUCT('DCF Valuation'!$B$6:$F$6,1/(1+0.0736)^'DCF Valuation'!$B$7:$F$7)+('DCF Valuation'!$F$6*(1+0.025)/(0.0736-0.025))/(1+0.0736)^5-'DCF Valuation'!$B$28)/'DCF Valuation'!$B$32 -> 309.3379 | E9: =(SUMPRODUCT('DCF Valuation'!$B$6:$F$6,1/(1+0.0736)^'DCF Valuation'!$B$7:$F$7)+('DCF Valuation'!$F$6*(1+0.03)/(0.0736-0.03))/(1+0.0736)^5-'DCF Valuation'!$B$28)/'DCF Valuation'!$B$32 -> 338.25554 | F9: =(SUMPRODUCT('DCF Valuation'!$B$6:$F$6,1/(1+0.0736)^'DCF Valuation'!$B$7:$F$7)+('DCF Valuation'!$F$6*(1+0.035)/(0.0736-0.035))/(1+0.0736)^5-'DCF Valuation'!$B$28)/'DCF Valuation'!$B$32 -> 374.66481
A10: 0.0786 | B10: =(SUMPRODUCT('DCF Valuation'!$B$6:$F$6,1/(1+0.0786)^'DCF Valuation'!$B$7:$F$7)+('DCF Valuation'!$F$6*(1+0.015)/(0.0786-0.015))/(1+0.0786)^5-'DCF Valuation'!$B$28)/'DCF Valuation'!$B$32 -> 245.83311 | C10: =(SUMPRODUCT('DCF Valuation'!$B$6:$F$6,1/(1+0.0786)^'DCF Valuation'!$B$7:$F$7)+('DCF Valuation'!$F$6*(1+0.02)/(0.0786-0.02))/(1+0.0786)^5-'DCF Valuation'!$B$28)/'DCF Valuation'!$B$32 -> 261.97147 | D10: =(SUMPRODUCT('DCF Valuation'!$B$6:$F$6,1/(1+0.0786)^'DCF Valuation'!$B$7:$F$7)+('DCF Valuation'!$F$6*(1+0.025)/(0.0786-0.025))/(1+0.0786)^5-'DCF Valuation'!$B$28)/'DCF Valuation'!$B$32 -> 281.12071 | E10: =(SUMPRODUCT('DCF Valuation'!$B$6:$F$6,1/(1+0.0786)^'DCF Valuation'!$B$7:$F$7)+('DCF Valuation'!$F$6*(1+0.03)/(0.0786-0.03))/(1+0.0786)^5-'DCF Valuation'!$B$28)/'DCF Valuation'!$B$32 -> 304.21013 | F10: =(SUMPRODUCT('DCF Valuation'!$B$6:$F$6,1/(1+0.0786)^'DCF Valuation'!$B$7:$F$7)+('DCF Valuation'!$F$6*(1+0.035)/(0.0786-0.035))/(1+0.0786)^5-'DCF Valuation'!$B$28)/'DCF Valuation'!$B$32 -> 332.59529
A11: 0.0836 | B11: =(SUMPRODUCT('DCF Valuation'!$B$6:$F$6,1/(1+0.0836)^'DCF Valuation'!$B$7:$F$7)+('DCF Valuation'!$F$6*(1+0.015)/(0.0836-0.015))/(1+0.0836)^5-'DCF Valuation'!$B$28)/'DCF Valuation'!$B$32 -> 228.35761 | C11: =(SUMPRODUCT('DCF Valuation'!$B$6:$F$6,1/(1+0.0836)^'DCF Valuation'!$B$7:$F$7)+('DCF Valuation'!$F$6*(1+0.02)/(0.0836-0.02))/(1+0.0836)^5-'DCF Valuation'!$B$28)/'DCF Valuation'!$B$32 -> 241.89074 | D11: =(SUMPRODUCT('DCF Valuation'!$B$6:$F$6,1/(1+0.0836)^'DCF Valuation'!$B$7:$F$7)+('DCF Valuation'!$F$6*(1+0.025)/(0.0836-0.025))/(1+0.0836)^5-'DCF Valuation'!$B$28)/'DCF Valuation'!$B$32 -> 257.73329 | E11: =(SUMPRODUCT('DCF Valuation'!$B$6:$F$6,1/(1+0.0836)^'DCF Valuation'!$B$7:$F$7)+('DCF Valuation'!$F$6*(1+0.03)/(0.0836-0.03))/(1+0.0836)^5-'DCF Valuation'!$B$28)/'DCF Valuation'!$B$32 -> 276.53154 | F11: =(SUMPRODUCT('DCF Valuation'!$B$6:$F$6,1/(1+0.0836)^'DCF Valuation'!$B$7:$F$7)+('DCF Valuation'!$F$6*(1+0.035)/(0.0836-0.035))/(1+0.0836)^5-'DCF Valuation'!$B$28)/'DCF Valuation'!$B$32 -> 299.19773
A12: 0.0886 | B12: =(SUMPRODUCT('DCF Valuation'!$B$6:$F$6,1/(1+0.0886)^'DCF Valuation'!$B$7:$F$7)+('DCF Valuation'!$F$6*(1+0.015)/(0.0886-0.015))/(1+0.0886)^5-'DCF Valuation'!$B$28)/'DCF Valuation'!$B$32 -> 213.26899 | C12: =(SUMPRODUCT('DCF Valuation'!$B$6:$F$6,1/(1+0.0886)^'DCF Valuation'!$B$7:$F$7)+('DCF Valuation'!$F$6*(1+0.02)/(0.0886-0.02))/(1+0.0886)^5-'DCF Valuation'!$B$28)/'DCF Valuation'!$B$32 -> 224.75001 | D12: =(SUMPRODUCT('DCF Valuation'!$B$6:$F$6,1/(1+0.0886)^'DCF Valuation'!$B$7:$F$7)+('DCF Valuation'!$F$6*(1+0.025)/(0.0886-0.025))/(1+0.0886)^5-'DCF Valuation'!$B$28)/'DCF Valuation'!$B$32 -> 238.03622 | E12: =(SUMPRODUCT('DCF Valuation'!$B$6:$F$6,1/(1+0.0886)^'DCF Valuation'!$B$7:$F$7)+('DCF Valuation'!$F$6*(1+0.03)/(0.0886-0.03))/(1+0.0886)^5-'DCF Valuation'!$B$28)/'DCF Valuation'!$B$32 -> 253.5897 | F12: =(SUMPRODUCT('DCF Valuation'!$B$6:$F$6,1/(1+0.0886)^'DCF Valuation'!$B$7:$F$7)+('DCF Valuation'!$F$6*(1+0.035)/(0.0886-0.035))/(1+0.0886)^5-'DCF Valuation'!$B$28)/'DCF Valuation'!$B$32 -> 272.04495
A13: 0.0936 | B13: =(SUMPRODUCT('DCF Valuation'!$B$6:$F$6,1/(1+0.0936)^'DCF Valuation'!$B$7:$F$7)+('DCF Valuation'!$F$6*(1+0.015)/(0.0936-0.015))/(1+0.0936)^5-'DCF Valuation'!$B$28)/'DCF Valuation'!$B$32 -> 200.11146 | C13: =(SUMPRODUCT('DCF Valuation'!$B$6:$F$6,1/(1+0.0936)^'DCF Valuation'!$B$7:$F$7)+('DCF Valuation'!$F$6*(1+0.02)/(0.0936-0.02))/(1+0.0936)^5-'DCF Valuation'!$B$28)/'DCF Valuation'!$B$32 -> 209.94979 | D13: =(SUMPRODUCT('DCF Valuation'!$B$6:$F$6,1/(1+0.0936)^'DCF Valuation'!$B$7:$F$7)+('DCF Valuation'!$F$6*(1+0.025)/(0.0936-0.025))/(1+0.0936)^5-'DCF Valuation'!$B$28)/'DCF Valuation'!$B$32 -> 221.22228 | E13: =(SUMPRODUCT('DCF Valuation'!$B$6:$F$6,1/(1+0.0936)^'DCF Valuation'!$B$7:$F$7)+('DCF Valuation'!$F$6*(1+0.03)/(0.0936-0.03))/(1+0.0936)^5-'DCF Valuation'!$B$28)/'DCF Valuation'!$B$32 -> 234.26717 | F13: =(SUMPRODUCT('DCF Valuation'!$B$6:$F$6,1/(1+0.0936)^'DCF Valuation'!$B$7:$F$7)+('DCF Valuation'!$F$6*(1+0.035)/(0.0936-0.035))/(1+0.0936)^5-'DCF Valuation'!$B$28)/'DCF Valuation'!$B$32 -> 249.53815
A15: Base case (WACC 7.9%, g 2.5%) is highlighted implicitly by row 4 (0.0786 nearest), column 3 (2.5%) above.
A17: TABLE 2: Implied Price per Share — Revenue CAGR (FY26-30E, rows) vs. Terminal EBITDA Margin (columns)
A19: Rev CAGR \ FY30E EBITDA Margin | B19: 0.037 | C19: 0.04 | D19: 0.043 | E19: 0.046 | F19: 0.049
A20: 0.055 | B20: =((275235*(1+0.055)^5)*0.037*18-'DCF Valuation'!$B$28)/'DCF Valuation'!$B$32 -> 556.23061 | C20: =((275235*(1+0.055)^5)*0.04*18-'DCF Valuation'!$B$28)/'DCF Valuation'!$B$32 -> 600.02981 | D20: =((275235*(1+0.055)^5)*0.043*18-'DCF Valuation'!$B$28)/'DCF Valuation'!$B$32 -> 643.829 | E20: =((275235*(1+0.055)^5)*0.046*18-'DCF Valuation'!$B$28)/'DCF Valuation'!$B$32 -> 687.62819 | F20: =((275235*(1+0.055)^5)*0.049*18-'DCF Valuation'!$B$28)/'DCF Valuation'!$B$32 -> 731.42738
A21: 0.065 | B21: =((275235*(1+0.065)^5)*0.037*18-'DCF Valuation'!$B$28)/'DCF Valuation'!$B$32 -> 582.32199 | C21: =((275235*(1+0.065)^5)*0.04*18-'DCF Valuation'!$B$28)/'DCF Valuation'!$B$32 -> 628.2367 | D21: =((275235*(1+0.065)^5)*0.043*18-'DCF Valuation'!$B$28)/'DCF Valuation'!$B$32 -> 674.15141 | E21: =((275235*(1+0.065)^5)*0.046*18-'DCF Valuation'!$B$28)/'DCF Valuation'!$B$32 -> 720.06612 | F21: =((275235*(1+0.065)^5)*0.049*18-'DCF Valuation'!$B$28)/'DCF Valuation'!$B$32 -> 765.98083
A22: 0.075 | B22: =((275235*(1+0.075)^5)*0.037*18-'DCF Valuation'!$B$28)/'DCF Valuation'!$B$32 -> 609.41195 | C22: =((275235*(1+0.075)^5)*0.04*18-'DCF Valuation'!$B$28)/'DCF Valuation'!$B$32 -> 657.52315 | D22: =((275235*(1+0.075)^5)*0.043*18-'DCF Valuation'!$B$28)/'DCF Valuation'!$B$32 -> 705.63434 | E22: =((275235*(1+0.075)^5)*0.046*18-'DCF Valuation'!$B$28)/'DCF Valuation'!$B$32 -> 753.74553 | F22: =((275235*(1+0.075)^5)*0.049*18-'DCF Valuation'!$B$28)/'DCF Valuation'!$B$32 -> 801.85672
A23: 0.085 | B23: =((275235*(1+0.085)^5)*0.037*18-'DCF Valuation'!$B$28)/'DCF Valuation'!$B$32 -> 637.52888 | C23: =((275235*(1+0.085)^5)*0.04*18-'DCF Valuation'!$B$28)/'DCF Valuation'!$B$32 -> 687.91983 | D23: =((275235*(1+0.085)^5)*0.043*18-'DCF Valuation'!$B$28)/'DCF Valuation'!$B$32 -> 738.31077 | E23: =((275235*(1+0.085)^5)*0.046*18-'DCF Valuation'!$B$28)/'DCF Valuation'!$B$32 -> 788.70171 | F23: =((275235*(1+0.085)^5)*0.049*18-'DCF Valuation'!$B$28)/'DCF Valuation'!$B$32 -> 839.09266
A24: 0.095 | B24: =((275235*(1+0.095)^5)*0.037*18-'DCF Valuation'!$B$28)/'DCF Valuation'!$B$32 -> 666.70171 | C24: =((275235*(1+0.095)^5)*0.04*18-'DCF Valuation'!$B$28)/'DCF Valuation'!$B$32 -> 719.45802 | D24: =((275235*(1+0.095)^5)*0.043*18-'DCF Valuation'!$B$28)/'DCF Valuation'!$B$32 -> 772.21433 | E24: =((275235*(1+0.095)^5)*0.046*18-'DCF Valuation'!$B$28)/'DCF Valuation'!$B$32 -> 824.97064 | F24: =((275235*(1+0.095)^5)*0.049*18-'DCF Valuation'!$B$28)/'DCF Valuation'!$B$32 -> 877.72694

Sheet Trading Comps
A1: Costco Wholesale Corporation — Trading Comparables Analysis
A2: Task 3: Valuation Analysis | Market data as of September 18-19, 2026. Sources: stockanalysis.com, Yahoo Finance, GuruFocus (see cell comments).
A4: Company | B4: Ticker | C4: Mkt Cap ($B) | D4: EV/EBITDA (TTM) | E4: Fwd P/E | F4: Trailing P/E | G4: Rev Growth (latest FY) | H4: Beta
A5: Walmart Inc. | B5: WMT | C5: 846.8 | D5: 20.66 | E5: 35.58 | F5: 38.68 | G5: 0.0473 | H5: 0.59
A6: Target Corporation | B6: TGT | C6: 75.1 | D6: 9.59 | E6: 17.12 | F6: 15.81 | G6: -0.0168 | H6: 0.97
A7: BJ's Wholesale Club Holdings | B7: BJ | C7: 12.4 | D7: 13.26 | E7: 20.46 | F7: 21.17 | G7: 0.0466 | H7: 0.33
A8: Dollar General Corporation | B8: DG | C8: 29 | D8: 11.96 | E8: 15.68 | F8: 16.71 | G8: 0.04 | H8: 0.25
A9: PriceSmart, Inc. | B9: PSMT | C9: 4.96 | D9: 14.38 | E9: 26.35 | F9: 32.47 | G9: 0.095 | H9: 0.76
A11: COSTCO WHOLESALE CORPORATION (target) | B11: COST | C11: 397.1 | D11: 29.63 | E11: 43.25 | F11: 45.04 | G11: 0.102 | H11: 0.86
A13: STATISTICAL SUMMARY (peer set only, excl. Costco)
A14: Maximum | C14: =MAX(C5:C9) -> 846.8 | D14: =MAX(D5:D9) -> 20.66 | E14: =MAX(E5:E9) -> 35.58 | F14: =MAX(F5:F9) -> 38.68 | G14: =MAX(G5:G9) -> 0.095 | H14: =MAX(H5:H9) -> 0.97
A15: 75th Percentile | C15: =QUARTILE(C5:C9,3) -> 75.1 | D15: =QUARTILE(D5:D9,3) -> 14.38 | E15: =QUARTILE(E5:E9,3) -> 26.35 | F15: =QUARTILE(F5:F9,3) -> 32.47 | G15: =QUARTILE(G5:G9,3) -> 0.0473 | H15: =QUARTILE(H5:H9,3) -> 0.76
A16: Median | C16: =MEDIAN(C5:C9) -> 29 | D16: =MEDIAN(D5:D9) -> 13.26 | E16: =MEDIAN(E5:E9) -> 20.46 | F16: =MEDIAN(F5:F9) -> 21.17 | G16: =MEDIAN(G5:G9) -> 0.0466 | H16: =MEDIAN(H5:H9) -> 0.59
A17: 25th Percentile | C17: =QUARTILE(C5:C9,1) -> 12.4 | D17: =QUARTILE(D5:D9,1) -> 11.96 | E17: =QUARTILE(E5:E9,1) -> 17.12 | F17: =QUARTILE(F5:F9,1) -> 16.71 | G17: =QUARTILE(G5:G9,1) -> 0.04 | H17: =QUARTILE(H5:H9,1) -> 0.33
A18: Minimum | C18: =MIN(C5:C9) -> 4.96 | D18: =MIN(D5:D9) -> 9.59 | E18: =MIN(E5:E9) -> 15.68 | F18: =MIN(F5:F9) -> 15.81 | G18: =MIN(G5:G9) -> -0.0168 | H18: =MIN(H5:H9) -> 0.25
A20: Note: Market data as of September 18-19, 2026. TTM = trailing twelve months. Sources: stockanalysis.com, Yahoo Finance, GuruFocus, MultiplesVC (see cell comments per company). All figures independently cross-checked against at least one additional source where noted in Task 1 research.
A22: APPLY PEER MULTIPLES TO COSTCO FY2026E ESTIMATES
A23: Costco FY2026E EBITDA ($mm) | C23: ='Income Statement'!G23+'DCF Inputs'!G10 -> 13892.554
A24: Costco FY2026E Diluted EPS ($) | C24: ='Income Statement'!G40 -> 19.82901
A26: Basis | B26: Peer Multiple | C26: Implied EV/Equity Value ($mm) | D26: Implied Price/Share
A27: EV/EBITDA — 25th pctile | B27: =D17 -> 11.96 | C27: =C23*B27-'DCF Valuation'!$B$28 -> 173268.94 | D27: =C27/'DCF Valuation'!$B$32 -> 390.68533
A28: EV/EBITDA — Median | B28: =D16 -> 13.26 | C28: =C23*B28-'DCF Valuation'!$B$28 -> 191329.26 | D28: =C28/'DCF Valuation'!$B$32 -> 431.40759
A29: EV/EBITDA — 75th pctile | B29: =D15 -> 14.38 | C29: =C23*B29-'DCF Valuation'!$B$28 -> 206888.92 | D29: =C29/'DCF Valuation'!$B$32 -> 466.49137
A30: Fwd P/E — 25th pctile | B30: =E17 -> 17.12 | C30: =D30*'DCF Valuation'!$B$32 -> 150556.12 | D30: =C24*B30 -> 339.47265
A31: Fwd P/E — Median | B31: =E16 -> 20.46 | C31: =D31*'DCF Valuation'!$B$32 -> 179928.64 | D31: =C24*B31 -> 405.70155
A32: Fwd P/E — 75th pctile | B32: =E15 -> 26.35 | C32: =D32*'DCF Valuation'!$B$32 -> 231726.27 | D32: =C24*B32 -> 522.49442
A34: Trading comps blended range (avg of EV/EBITDA and Fwd P/E medians): | D34: =AVERAGE(D28,D31) -> 418.55457

Sheet Valuation Summary
B1: Costco Wholesale Corporation — Valuation Summary & Recommendation
B2: Task 3: Valuation Analysis | Prepared September 20, 2026 (pre-Q4 FY2026 earnings, due Sept 24, 2026)
B4: VALUATION METHOD SUMMARY
B5: Method | C5: Low | D5: Base/Median | E5: High | F5: Weight | G5: Weighted Contribution
B6: DCF (5-yr explicit + Gordon Growth TV) | C6: ='DCF Sensitivity'!B13 -> 200.11146 | D6: ='DCF Valuation'!B33 -> 281.09872 | E6: ='DCF Sensitivity'!B7 -> 319.95258 | F6: 0.2 | G6: =D6*F6 -> 56.219743
B7: Trading Comps (peer EV/EBITDA + Fwd P/E) | C7: ='Trading Comps'!D30 -> 339.47265 | D7: ='Trading Comps'!D34 -> 418.55457 | E7: ='Trading Comps'!D32 -> 522.49442 | F7: 0.25 | G7: =D7*F7 -> 104.63864
B8: Memo: trailing P/E multiple applied | C8: 39.51 | D8: 46.7 | E8: 51.75
B9: Historical Own-Multiple Reversion | C9: =C8*'Income Statement'!G40 -> 783.44419 | D9: =D8*'Income Statement'!G40 -> 926.01477 | E9: =E8*'Income Statement'!G40 -> 1026.1513 | F9: 0.3 | G9: =D9*F9 -> 277.80443
B10: Scenario-Based (Bull/Base/Bear, prob-weighted) | C10: =(Scenarios!D34*30)/(1+'DCF Inputs'!B27)^4 -> 460.88484 | D10: =(Scenarios!C34*40)/(1+'DCF Inputs'!B27)^4 -> 770.08699 | E10: =(Scenarios!B34*45)/(1+'DCF Inputs'!B27)^4 -> 1031.88 | F10: 0.25 | G10: =(C10*0.2+D10*0.6+E10*0.2)*F10 -> 190.15129
B12: WEIGHTED AVERAGE 12-MONTH PRICE TARGET | F12: =SUM(F6:F10) -> 1 | G12: =SUM(G6:G10) -> 628.81411
B14: CURRENT PRICE, UPSIDE/DOWNSIDE & RATING
B15: Current share price (as of Sept 18-19, 2026) | C15: ='DCF Valuation'!B34 -> 895
B16: 12-month price target (rounded) | C16: =ROUND(G12,-1) -> 630
B17: Implied upside / (downside) to target | C17: =C16/C15-1 -> -0.29608939
B18: Suggested entry zone for new capital | C18: $600 - $700
B20: RATING: H O L D
B21: Not a Buy at current levels; not a Sell for existing holders. See rationale below.
B23: SANITY CHECKS PERFORMED
B24: 1. Historical multiple check
B25: COST's current trailing P/E (~45-48x) sits ~16% above its own 10-year average (39.51x) but roughly in line with its 3-year average (51.75x) — i.e., rich vs. long history, not vs. recent trading range.
B27: 2. Peer comparison check
B28: COST trades at a ~2.2x premium to peer median EV/EBITDA (29.6x vs. 13.3x) and ~2.1x premium to peer median forward P/E (43.3x vs. 20.5x) — the largest such gap of the peer set, only partially justified by superior growth/margin/moat characteristics documented in Task 1.
B30: 3. Implied growth check (reverse DCF)
B31: At the current price, holding WACC at 7.9%, the DCF implies a ~6.4% PERPETUAL growth rate — well above typical 2.0-3.0% terminal-growth conventions and above long-run nominal GDP growth. The market is pricing in either much stronger perpetual growth than is conventional to assume, a lower true discount rate than CAPM implies, or simply an extended 'quality premium' that persists beyond any explicit forecast period.
B33: 4. Market cap reasonableness
B34: At ~$397bn, COST is the 3rd-largest pure retailer globally (per Task 1 research) — larger than Target, BJ's, Dollar General and PriceSmart combined by roughly 3x. Scale is real and defensible; the question is entirely about the PRICE paid for that scale, not whether the scale itself is plausible.
B36: 5. Terminal value check
... B45: Note: Wall Street sell-side consensus (35 analysts per S&P Global/stockanalysis.com, Sept 2026) is Buy / Moderate Buy with an average target of ~$1,072-1,089 (range $740-$1,315) — meaningfully ABOVE this independent analysis. See Valuation Analysis document for full discussion of this divergence.

Sheet Catalysts & Risks
B1: Costco Wholesale Corporation — Key Catalysts & Risks
B2: Task 3: Valuation Analysis | Supporting detail for the price target and HOLD rating
B4: KEY INVESTMENT CATALYSTS (upside drivers)
B5: # | C5: Catalyst | D5: Probability | E5: Impact | F5: Detail
